Workbook

Sheet Summary
B2: FlexCapPro — Regression Test Suite Summary
B3: QA regression coverage across Register, Login, Supplier, Buyer, Email & In-App Notification modules — live view, updates automatically as Status is filled in
B5: TOTAL TEST CASES | G5: POSITIVE TEST CASES | L5: NEGATIVE TEST CASES | Q5: OTHER (DEFECT LOGS)
B6: =COUNTA(Register!D2:D41)+COUNTA(Login!D2:D34)+COUNTA('Forgot Password'!D2:D34)+COUNTA('Supplier Onboarding'!D2:D256)+COUNTA('Buyer Onboarding'!D2:D223)+COUNTA('Supplier Dashboard page'!D2:D109)+COUNTA('Supplier Buyer page'!D2:D115)+COUNTA('Supplier Reports Page'!D2:D75)+COUNTA('Supplier Invoices Page'!D2:D132)+COUNTA('Supplier Admin page '!D2:D84)+COUNTA('Supplier Help and Support Page'!D2:D55)+COUNTA('Supplier Entity'!D2:D305)+COUNTA('Buyer Dashboard'!D2:D83)+COUNTA('Add Supplier Page'!D2:D43)+COUNTA('Buyer Report Page'!D2:D75)+COUNTA('Buyer Help and Support Page'!D2:D55)+COUNTA('Buyer Entity Page'!D2:D258)+COUNTA('Buyer Add Card Page '!D2:D38)+COUNTA('Buyer Payable Page'!D2:D85)+COUNTA('Email Notification'!D2:D82)+COUNTA('In_App Notification'!D2:D65) -> 2201 | G6: =COUNTIF(Register!D2:D41,"*Positive*")+COUNTIF(Login!D2:D34,"*Positive*")+COUNTIF('Forgot Password'!D2:D34,"*Positive*")+COUNTIF('Supplier Onboarding'!D2:D256,"*Positive*")+COUNTIF('Buyer Onboarding'!D2:D223,"*Positive*")+COUNTIF('Supplier Dashboard page'!D2:D109,"*Positive*")+COUNTIF('Supplier Buyer page'!D2:D115,"*Positive*")+COUNTIF('Supplier Reports Page'!D2:D75,"*Positive*")+COUNTIF('Supplier Invoices Page'!D2:D132,"*Positive*")+COUNTIF('Supplier Admin page '!D2:D84,"*Positive*")+COUNTIF('Supplier Help and Support Page'!D2:D55,"*Positive*")+COUNTIF('Supplier Entity'!D2:D305,"*Positive*")+COUNTIF('Buyer Dashboard'!D2:D83,"*Positive*")+COUNTIF('Add Supplier Page'!D2:D43,"*Positive*")+COUNTIF('Buyer Report Page'!D2:D75,"*Positive*")+COUNTIF('Buyer Help and Support Page'!D2:D55,"*Positive*")+COUNTIF('Buyer Entity Page'!D2:D258,"*Positive*")+COUNTIF('Buyer Add Card Page '!D2:D38,"*Positive*")+COUNTIF('Buyer Payable Page'!D2:D85,"*Positive*")+COUNTIF('Email Notification'!D2:D82,"*Positive*")+COUNTIF('In_App Notification'!D2:D65,"*Positive*") -> 1072 | L6: =COUNTIF(Register!D2:D41,"*Negative*")+COUNTIF(Login!D2:D34,"*Negative*")+COUNTIF('Forgot Password'!D2:D34,"*Negative*")+COUNTIF('Supplier Onboarding'!D2:D256,"*Negative*")+COUNTIF('Buyer Onboarding'!D2:D223,"*Negative*")+COUNTIF('Supplier Dashboard page'!D2:D109,"*Negative*")+COUNTIF('Supplier Buyer page'!D2:D115,"*Negative*")+COUNTIF('Supplier Reports Page'!D2:D75,"*Negative*")+COUNTIF('Supplier Invoices Page'!D2:D132,"*Negative*")+COUNTIF('Supplier Admin page '!D2:D84,"*Negative*")+COUNTIF('Supplier Help and Support Page'!D2:D55,"*Negative*")+COUNTIF('Supplier Entity'!D2:D305,"*Negative*")+COUNTIF('Buyer Dashboard'!D2:D83,"*Negative*")+COUNTIF('Add Supplier Page'!D2:D43,"*Negative*")+COUNTIF('Buyer Report Page'!D2:D75,"*Negative*")+COUNTIF('Buyer Help and Support Page'!D2:D55,"*Negative*")+COUNTIF('Buyer Entity Page'!D2:D258,"*Negative*")+COUNTIF('Buyer Add Card Page '!D2:D38,"*Negative*")+COUNTIF('Buyer Payable Page'!D2:D85,"*Negative*")+COUNTIF('Email Notification'!D2:D82,"*Negative*")+COUNTIF('In_App Notification'!D2:D65,"*Negative*") -> 1120 | Q6: =COUNTA(Register!D2:D41)+COUNTA(Login!D2:D34)+COUNTA('Forgot Password'!D2:D34)+COUNTA('Supplier Onboarding'!D2:D256)+COUNTA('Buyer Onboarding'!D2:D223)+COUNTA('Supplier Dashboard page'!D2:D109)+COUNTA('Supplier Buyer page'!D2:D115)+COUNTA('Supplier Reports Page'!D2:D75)+COUNTA('Supplier Invoices Page'!D2:D132)+COUNTA('Supplier Admin page '!D2:D84)+COUNTA('Supplier Help and Support Page'!D2:D55)+COUNTA('Supplier Entity'!D2:D305)+COUNTA('Buyer Dashboard'!D2:D83)+COUNTA('Add Supplier Page'!D2:D43)+COUNTA('Buyer Report Page'!D2:D75)+COUNTA('Buyer Help and Support Page'!D2:D55)+COUNTA('Buyer Entity Page'!D2:D258)+COUNTA('Buyer Add Card Page '!D2:D38)+COUNTA('Buyer Payable Page'!D2:D85)+COUNTA('Email Notification'!D2:D82)+COUNTA('In_App Notification'!D2:D65)-(COUNTIF(Register!D2:D41,"*Positive*")+COUNTIF(Login!D2:D34,"*Positive*")+COUNTIF('Forgot Password'!D2:D34,"*Positive*")+COUNTIF('Supplier Onboarding'!D2:D256,"*Positive*")+COUNTIF('Buyer Onboarding'!D2:D223,"*Positive*")+COUNTIF('Supplier Dashboard page'!D2:D109,"*Positive*")+COUNTIF('Supplier Buyer page'!D2:D115,"*Positive*")+COUNTIF('Supplier Reports Page'!D2:D75,"*Positive*")+COUNTIF('Supplier Invoices Page'!D2:D132,"*Positive*")+COUNTIF('Supplier Admin page '!D2:D84,"*Positive*")+COUNTIF('Supplier Help and Support Page'!D2:D55,"*Positive*")+COUNTIF('Supplier Entity'!D2:D305,"*Positive*")+COUNTIF('Buyer Dashboard'!D2:D83,"*Positive*")+COUNTIF('Add Supplier Page'!D2:D43,"*Positive*")+COUNTIF('Buyer Report Page'!D2:D75,"*Positive*")+COUNTIF('Buyer Help and Support Page'!D2:D55,"*Positive*")+COUNTIF('Buyer Entity Page'!D2:D258,"*Positive*")+COUNTIF('Buyer Add Card Page '!D2:D38,"*Positive*")+COUNTIF('Buyer Payable Page'!D2:D85,"*Positive*")+COUNTIF('Email Notification'!D2:D82,"*Positive*")+COUNTIF('In_App Notification'!D2:D65,"*Positive*"))-(COUNTIF(Register!D2:D41,"*Negative*")+COUNTIF(Login!D2:D34,"*Negative*")+COUNTIF('Forgot Password'!D2:D34,"*Negative*")+COUNTIF('Supplier Onboarding'!D2:D256,"*Negative*")+COUNTIF('Buyer Onboarding'!D2:D223,"*Negative*")+COUNTIF('Supplier Dashboard page'!D2:D109,"*Negative*")+COUNTIF('Supplier Buyer page'!D2:D115,"*Negative*")+COUNTIF('Supplier Reports Page'!D2:D75,"*Negative*")+COUNTIF('Supplier Invoices Page'!D2:D132,"*Negative*")+COUNTIF('Supplier Admin page '!D2:D84,"*Negative*")+COUNTIF('Supplier Help and Support Page'!D2:D55,"*Negative*")+COUNTIF('Supplier Entity'!D2:D305,"*Negative*")+COUNTIF('Buyer Dashboard'!D2:D83,"*Negative*")+COUNTIF('Add Supplier Page'!D2:D43,"*Negative*")+COUNTIF('Buyer Report Page'!D2:D75,"*Negative*")+COUNTIF('Buyer Help and Support Page'!D2:D55,"*Negative*")+COUNTIF('Buyer Entity Page'!D2:D258,"*Negative*")+COUNTIF('Buyer Add Card Page '!D2:D38,"*Negative*")+COUNTIF('Buyer Payable Page'!D2:D85,"*Negative*")+COUNTIF('Email Notification'!D2:D82,"*Negative*")+COUNTIF('In_App Notification'!D2:D65,"*Negative*")) -> 9
B7: Across all 21 modules | G7: Standard/happy-path flows | L7: Edge cases & error handling | Q7: Defects found during authoring
B10: PASSED | G10: FAILED | L10: BLOCKED | Q10: NOT EXECUTED / PENDING
B11: =COUNTIF(Register!J2:J41,"Pass")+COUNTIF(Login!J2:J34,"Pass")+COUNTIF('Forgot Password'!J2:J34,"Pass")+COUNTIF('Supplier Onboarding'!J2:J256,"Pass")+COUNTIF('Buyer Onboarding'!J2:J223,"Pass")+COUNTIF('Supplier Dashboard page'!J2:J109,"Pass")+COUNTIF('Supplier Buyer page'!J2:J115,"Pass")+COUNTIF('Supplier Reports Page'!J2:J75,"Pass")+COUNTIF('Supplier Invoices Page'!J2:J132,"Pass")+COUNTIF('Supplier Admin page '!J2:J84,"Pass")+COUNTIF('Supplier Help and Support Page'!J2:J55,"Pass")+COUNTIF('Supplier Entity'!J2:J305,"Pass")+COUNTIF('Buyer Dashboard'!J2:J83,"Pass")+COUNTIF('Add Supplier Page'!J2:J43,"Pass")+COUNTIF('Buyer Report Page'!J2:J75,"Pass")+COUNTIF('Buyer Help and Support Page'!J2:J55,"Pass")+COUNTIF('Buyer Entity Page'!J2:J258,"Pass")+COUNTIF('Buyer Add Card Page '!J2:J38,"Pass")+COUNTIF('Buyer Payable Page'!J2:J85,"Pass")+COUNTIF('Email Notification'!J2:J82,"Pass")+COUNTIF('In_App Notification'!J2:J65,"Pass") -> 28 | G11: =COUNTIF(Register!J2:J41,"Fail")+COUNTIF(Login!J2:J34,"Fail")+COUNTIF('Forgot Password'!J2:J34,"Fail")+COUNTIF('Supplier Onboarding'!J2:J256,"Fail")+COUNTIF('Buyer Onboarding'!J2:J223,"Fail")+COUNTIF('Supplier Dashboard page'!J2:J109,"Fail")+COUNTIF('Supplier Buyer page'!J2:J115,"Fail")+COUNTIF('Supplier Reports Page'!J2:J75,"Fail")+COUNTIF('Supplier Invoices Page'!J2:J132,"Fail")+COUNTIF('Supplier Admin page '!J2:J84,"Fail")+COUNTIF('Supplier Help and Support Page'!J2:J55,"Fail")+COUNTIF('Supplier Entity'!J2:J305,"Fail")+COUNTIF('Buyer Dashboard'!J2:J83,"Fail")+COUNTIF('Add Supplier Page'!J2:J43,"Fail")+COUNTIF('Buyer Report Page'!J2:J75,"Fail")+COUNTIF('Buyer Help and Support Page'!J2:J55,"Fail")+COUNTIF('Buyer Entity Page'!J2:J258,"Fail")+COUNTIF('Buyer Add Card Page '!J2:J38,"Fail")+COUNTIF('Buyer Payable Page'!J2:J85,"Fail")+COUNTIF('Email Notification'!J2:J82,"Fail")+COUNTIF('In_App Notification'!J2:J65,"Fail") -> 5 | L11: =COUNTIF(Register!J2:J41,"Blocked")+COUNTIF(Login!J2:J34,"Blocked")+COUNTIF('Forgot Password'!J2:J34,"Blocked")+COUNTIF('Supplier Onboarding'!J2:J256,"Blocked")+COUNTIF('Buyer Onboarding'!J2:J223,"Blocked")+COUNTIF('Supplier Dashboard page'!J2:J109,"Blocked")+COUNTIF('Supplier Buyer page'!J2:J115,"Blocked")+COUNTIF('Supplier Reports Page'!J2:J75,"Blocked")+COUNTIF('Supplier Invoices Page'!J2:J132,"Blocked")+COUNTIF('Supplier Admin page '!J2:J84,"Blocked")+COUNTIF('Supplier Help and Support Page'!J2:J55,"Blocked")+COUNTIF('Supplier Entity'!J2:J305,"Blocked")+COUNTIF('Buyer Dashboard'!J2:J83,"Blocked")+COUNTIF('Add Supplier Page'!J2:J43,"Blocked")+COUNTIF('Buyer Report Page'!J2:J75,"Blocked")+COUNTIF('Buyer Help and Support Page'!J2:J55,"Blocked")+COUNTIF('Buyer Entity Page'!J2:J258,"Blocked")+COUNTIF('Buyer Add Card Page '!J2:J38,"Blocked")+COUNTIF('Buyer Payable Page'!J2:J85,"Blocked")+COUNTIF('Email Notification'!J2:J82,"Blocked")+COUNTIF('In_App Notification'!J2:J65,"Blocked") -> 0 | Q11: =COUNTA(Register!D2:D41)+COUNTA(Login!D2:D34)+COUNTA('Forgot Password'!D2:D34)+COUNTA('Supplier Onboarding'!D2:D256)+COUNTA('Buyer Onboarding'!D2:D223)+COUNTA('Supplier Dashboard page'!D2:D109)+COUNTA('Supplier Buyer page'!D2:D115)+COUNTA('Supplier Reports Page'!D2:D75)+COUNTA('Supplier Invoices Page'!D2:D132)+COUNTA('Supplier Admin page '!D2:D84)+COUNTA('Supplier Help and Support Page'!D2:D55)+COUNTA('Supplier Entity'!D2:D305)+COUNTA('Buyer Dashboard'!D2:D83)+COUNTA('Add Supplier Page'!D2:D43)+COUNTA('Buyer Report Page'!D2:D75)+COUNTA('Buyer Help and Support Page'!D2:D55)+COUNTA('Buyer Entity Page'!D2:D258)+COUNTA('Buyer Add Card Page '!D2:D38)+COUNTA('Buyer Payable Page'!D2:D85)+COUNTA('Email Notification'!D2:D82)+COUNTA('In_App Notification'!D2:D65)-(COUNTIF(Register!J2:J41,"Pass")+COUNTIF(Login!J2:J34,"Pass")+COUNTIF('Forgot Password'!J2:J34,"Pass")+COUNTIF('Supplier Onboarding'!J2:J256,"Pass")+COUNTIF('Buyer Onboarding'!J2:J223,"Pass")+COUNTIF('Supplier Dashboard page'!J2:J109,"Pass")+COUNTIF('Supplier Buyer page'!J2:J115,"Pass")+COUNTIF('Supplier Reports Page'!J2:J75,"Pass")+COUNTIF('Supplier Invoices Page'!J2:J132,"Pass")+COUNTIF('Supplier Admin page '!J2:J84,"Pass")+COUNTIF('Supplier Help and Support Page'!J2:J55,"Pass")+COUNTIF('Supplier Entity'!J2:J305,"Pass")+COUNTIF('Buyer Dashboard'!J2:J83,"Pass")+COUNTIF('Add Supplier Page'!J2:J43,"Pass")+COUNTIF('Buyer Report Page'!J2:J75,"Pass")+COUNTIF('Buyer Help and Support Page'!J2:J55,"Pass")+COUNTIF('Buyer Entity Page'!J2:J258,"Pass")+COUNTIF('Buyer Add Card Page '!J2:J38,"Pass")+COUNTIF('Buyer Payable Page'!J2:J85,"Pass")+COUNTIF('Email Notification'!J2:J82,"Pass")+COUNTIF('In_App Notification'!J2:J65,"Pass"))-(COUNTIF(Register!J2:J41,"Fail")+COUNTIF(Login!J2:J34,"Fail")+COUNTIF('Forgot Password'!J2:J34,"Fail")+COUNTIF('Supplier Onboarding'!J2:J256,"Fail")+COUNTIF('Buyer Onboarding'!J2:J223,"Fail")+COUNTIF('Supplier Dashboard page'!J2:J109,"Fail")+COUNTIF('Supplier Buyer page'!J2:J115,"Fail")+COUNTIF('Supplier Reports Page'!J2:J75,"Fail")+COUNTIF('Supplier Invoices Page'!J2:J132,"Fail")+COUNTIF('Supplier Admin page '!J2:J84,"Fail")+COUNTIF('Supplier Help and Support Page'!J2:J55,"Fail")+COUNTIF('Supplier Entity'!J2:J305,"Fail")+COUNTIF('Buyer Dashboard'!J2:J83,"Fail")+COUNTIF('Add Supplier Page'!J2:J43,"Fail")+COUNTIF('Buyer Report Page'!J2:J75,"Fail")+COUNTIF('Buyer Help and Support Page'!J2:J55,"Fail")+COUNTIF('Buyer Entity Page'!J2:J258,"Fail")+COUNTIF('Buyer Add Card Page '!J2:J38,"Fail")+COUNTIF('Buyer Payable Page'!J2:J85,"Fail")+COUNTIF('Email Notification'!J2:J82,"Fail")+COUNTIF('In_App Notification'!J2:J65,"Fail"))-(COUNTIF(Register!J2:J41,"Blocked")+COUNTIF(Login!J2:J34,"Blocked")+COUNTIF('Forgot Password'!J2:J34,"Blocked")+COUNTIF('Supplier Onboarding'!J2:J256,"Blocked")+COUNTIF('Buyer Onboarding'!J2:J223,"Blocked")+COUNTIF('Supplier Dashboard page'!J2:J109,"Blocked")+COUNTIF('Supplier Buyer page'!J2:J115,"Blocked")+COUNTIF('Supplier Reports Page'!J2:J75,"Blocked")+COUNTIF('Supplier Invoices Page'!J2:J132,"Blocked")+COUNTIF('Supplier Admin page '!J2:J84,"Blocked")+COUNTIF('Supplier Help and Support Page'!J2:J55,"Blocked")+COUNTIF('Supplier Entity'!J2:J305,"Blocked")+COUNTIF('Buyer Dashboard'!J2:J83,"Blocked")+COUNTIF('Add Supplier Page'!J2:J43,"Blocked")+COUNTIF('Buyer Report Page'!J2:J75,"Blocked")+COUNTIF('Buyer Help and Support Page'!J2:J55,"Blocked")+COUNTIF('Buyer Entity Page'!J2:J258,"Blocked")+COUNTIF('Buyer Add Card Page '!J2:J38,"Blocked")+COUNTIF('Buyer Payable Page'!J2:J85,"Blocked")+COUNTIF('Email Notification'!J2:J82,"Blocked")+COUNTIF('In_App Notification'!J2:J65,"Blocked"))-(COUNTIF(Register!J2:J41,"Not Applicable")+COUNTIF(Login!J2:J34,"Not Applicable")+COUNTIF('Forgot Password'!J2:J34,"Not Applicable")+COUNTIF('Supplier Onboarding'!J2:J256,"Not Applicable")+COUNTIF('Buyer Onboarding'!J2:J223,"Not Applicable")+COUNTIF('Supplier Dashboard page'!J2:J109,"Not Applicable")+COUNTIF('Supplier Buyer page'!J2:J115,"Not Applicable")+COUNTIF('Supplier Reports Page'!J2:J75,"Not Applicable")+COUNTIF('Supplier Invoices Page'!J2:J132,"Not Applicable")+COUNTIF('Supplier Admin page '!J2:J84,"Not Applicable")+COUNTIF('Supplier Help and Support Page'!J2:J55,"Not Applicable")+COUNTIF('Supplier Entity'!J2:J305,"Not Applicable")+COUNTIF('Buyer Dashboard'!J2:J83,"Not Applicable")+COUNTIF('Add Supplier Page'!J2:J43,"Not Applicable")+COUNTIF('Buyer Report Page'!J2:J75,"Not Applicable")+COUNTIF('Buyer Help and Support Page'!J2:J55,"Not Applicable")+COUNTIF('Buyer Entity Page'!J2:J258,"Not Applicable")+COUNTIF('Buyer Add Card Page '!J2:J38,"Not Applicable")+COUNTIF('Buyer Payable Page'!J2:J85,"Not Applicable")+COUNTIF('Email Notification'!J2:J82,"Not Applicable")+COUNTIF('In_App Notification'!J2:J65,"Not Applicable")) -> 2168
B12: Executed & working as expected | G12: Executed & defect found | L12: Could not be executed | Q12: Yet to be run by QA
B15: EXECUTION HEALTH
B16: Execution % (Pass+Fail+Blocked / Total) | E16: Pass Rate % (Pass / Executed) | H16: High Priority Test Cases | K16: Medium Priority Test Cases | N16: Low Priority Test Cases
B17: =IFERROR((COUNTIF(Register!J2:J41,"Pass")+COUNTIF(Login!J2:J34,"Pass")+COUNTIF('Forgot Password'!J2:J34,"Pass")+COUNTIF('Supplier Onboarding'!J2:J256,"Pass")+COUNTIF('Buyer Onboarding'!J2:J223,"Pass")+COUNTIF('Supplier Dashboard page'!J2:J109,"Pass")+COUNTIF('Supplier Buyer page'!J2:J115,"Pass")+COUNTIF('Supplier Reports Page'!J2:J75,"Pass")+COUNTIF('Supplier Invoices Page'!J2:J132,"Pass")+COUNTIF('Supplier Admin page '!J2:J84,"Pass")+COUNTIF('Supplier Help and Support Page'!J2:J55,"Pass")+COUNTIF('Supplier Entity'!J2:J305,"Pass")+COUNTIF('Buyer Dashboard'!J2:J83,"Pass")+COUNTIF('Add Supplier Page'!J2:J43,"Pass")+COUNTIF('Buyer Report Page'!J2:J75,"Pass")+COUNTIF('Buyer Help and Support Page'!J2:J55,"Pass")+COUNTIF('Buyer Entity Page'!J2:J258,"Pass")+COUNTIF('Buyer Add Card Page '!J2:J38,"Pass")+COUNTIF('Buyer Payable Page'!J2:J85,"Pass")+COUNTIF('Email Notification'!J2:J82,"Pass")+COUNTIF('In_App Notification'!J2:J65,"Pass")+COUNTIF(Register!J2:J41,"Fail")+COUNTIF(Login!J2:J34,"Fail")+COUNTIF('Forgot Password'!J2:J34,"Fail")+COUNTIF('Supplier Onboarding'!J2:J256,"Fail")+COUNTIF('Buyer Onboarding'!J2:J223,"Fail")+COUNTIF('Supplier Dashboard page'!J2:J109,"Fail")+COUNTIF('Supplier Buyer page'!J2:J115,"Fail")+COUNTIF('Supplier Reports Page'!J2:J75,"Fail")+COUNTIF('Supplier Invoices Page'!J2:J132,"Fail")+COUNTIF('Supplier Admin page '!J2:J84,"Fail")+COUNTIF('Supplier Help and Support Page'!J2:J55,"Fail")+COUNTIF('Supplier Entity'!J2:J305,"Fail")+COUNTIF('Buyer Dashboard'!J2:J83,"Fail")+COUNTIF('Add Supplier Page'!J2:J43,"Fail")+COUNTIF('Buyer Report Page'!J2:J75,"Fail")+COUNTIF('Buyer Help and Support Page'!J2:J55,"Fail")+COUNTIF('Buyer Entity Page'!J2:J258,"Fail")+COUNTIF('Buyer Add Card Page '!J2:J38,"Fail")+COUNTIF('Buyer Payable Page'!J2:J85,"Fail")+COUNTIF('Email Notification'!J2:J82,"Fail")+COUNTIF('In_App Notification'!J2:J65,"Fail")+COUNTIF(Register!J2:J41,"Blocked")+COUNTIF(Login!J2:J34,"Blocked")+COUNTIF('Forgot Password'!J2:J34,"Blocked")+COUNTIF('Supplier Onboarding'!J2:J256,"Blocked")+COUNTIF('Buyer Onboarding'!J2:J223,"Blocked")+COUNTIF('Supplier Dashboard page'!J2:J109,"Blocked")+COUNTIF('Supplier Buyer page'!J2:J115,"Blocked")+COUNTIF('Supplier Reports Page'!J2:J75,"Blocked")+COUNTIF('Supplier Invoices Page'!J2:J132,"Blocked")+COUNTIF('Supplier Admin page '!J2:J84,"Blocked")+COUNTIF('Supplier Help and Support Page'!J2:J55,"Blocked")+COUNTIF('Supplier Entity'!J2:J305,"Blocked")+COUNTIF('Buyer Dashboard'!J2:J83,"Blocked")+COUNTIF('Add Supplier Page'!J2:J43,"Blocked")+COUNTIF('Buyer Report Page'!J2:J75,"Blocked")+COUNTIF('Buyer Help and Support Page'!J2:J55,"Blocked")+COUNTIF('Buyer Entity Page'!J2:J258,"Blocked")+COUNTIF('Buyer Add Card Page '!J2:J38,"Blocked")+COUNTIF('Buyer Payable Page'!J2:J85,"Blocked")+COUNTIF('Email Notification'!J2:J82,"Blocked")+COUNTIF('In_App Notification'!J2:J65,"Blocked"))/(COUNTA(Register!D2:D41)+COUNTA(Login!D2:D34)+COUNTA('Forgot Password'!D2:D34)+COUNTA('Supplier Onboarding'!D2:D256)+COUNTA('Buyer Onboarding'!D2:D223)+COUNTA('Supplier Dashboard page'!D2:D109)+COUNTA('Supplier Buyer page'!D2:D115)+COUNTA('Supplier Reports Page'!D2:D75)+COUNTA('Supplier Invoices Page'!D2:D132)+COUNTA('Supplier Admin page '!D2:D84)+COUNTA('Supplier Help and Support Page'!D2:D55)+COUNTA('Supplier Entity'!D2:D305)+COUNTA('Buyer Dashboard'!D2:D83)+COUNTA('Add Supplier Page'!D2:D43)+COUNTA('Buyer Report Page'!D2:D75)+COUNTA('Buyer Help and Support Page'!D2:D55)+COUNTA('Buyer Entity Page'!D2:D258)+COUNTA('Buyer Add Card Page '!D2:D38)+COUNTA('Buyer Payable Page'!D2:D85)+COUNTA('Email Notification'!D2:D82)+COUNTA('In_App Notification'!D2:D65)),0) -> 0.014993185 | E17: =IFERROR((COUNTIF(Register!J2:J41,"Pass")+COUNTIF(Login!J2:J34,"Pass")+COUNTIF('Forgot Password'!J2:J34,"Pass")+COUNTIF('Supplier Onboarding'!J2:J256,"Pass")+COUNTIF('Buyer Onboarding'!J2:J223,"Pass")+COUNTIF('Supplier Dashboard page'!J2:J109,"Pass")+COUNTIF('Supplier Buyer page'!J2:J115,"Pass")+COUNTIF('Supplier Reports Page'!J2:J75,"Pass")+COUNTIF('Supplier Invoices Page'!J2:J132,"Pass")+COUNTIF('Supplier Admin page '!J2:J84,"Pass")+COUNTIF('Supplier Help and Support Page'!J2:J55,"Pass")+COUNTIF('Supplier Entity'!J2:J305,"Pass")+COUNTIF('Buyer Dashboard'!J2:J83,"Pass")+COUNTIF('Add Supplier Page'!J2:J43,"Pass")+COUNTIF('Buyer Report Page'!J2:J75,"Pass")+COUNTIF('Buyer Help and Support Page'!J2:J55,"Pass")+COUNTIF('Buyer Entity Page'!J2:J258,"Pass")+COUNTIF('Buyer Add Card Page '!J2:J38,"Pass")+COUNTIF('Buyer Payable Page'!J2:J85,"Pass")+COUNTIF('Email Notification'!J2:J82,"Pass")+COUNTIF('In_App Notification'!J2:J65,"Pass"))/(COUNTIF(Register!J2:J41,"Pass")+COUNTIF(Login!J2:J34,"Pass")+COUNTIF('Forgot Password'!J2:J34,"Pass")+COUNTIF('Supplier Onboarding'!J2:J256,"Pass")+COUNTIF('Buyer Onboarding'!J2:J223,"Pass")+COUNTIF('Supplier Dashboard page'!J2:J109,"Pass")+COUNTIF('Supplier Buyer page'!J2:J115,"Pass")+COUNTIF('Supplier Reports Page'!J2:J75,"Pass")+COUNTIF('Supplier Invoices Page'!J2:J132,"Pass")+COUNTIF('Supplier Admin page '!J2:J84,"Pass")+COUNTIF('Supplier Help and Support Page'!J2:J55,"Pass")+COUNTIF('Supplier Entity'!J2:J305,"Pass")+COUNTIF('Buyer Dashboard'!J2:J83,"Pass")+COUNTIF('Add Supplier Page'!J2:J43,"Pass")+COUNTIF('Buyer Report Page'!J2:J75,"Pass")+COUNTIF('Buyer Help and Support Page'!J2:J55,"Pass")+COUNTIF('Buyer Entity Page'!J2:J258,"Pass")+COUNTIF('Buyer Add Card Page '!J2:J38,"Pass")+COUNTIF('Buyer Payable Page'!J2:J85,"Pass")+COUNTIF('Email Notification'!J2:J82,"Pass")+COUNTIF('In_App Notification'!J2:J65,"Pass")+COUNTIF(Register!J2:J41,"Fail")+COUNTIF(Login!J2:J34,"Fail")+COUNTIF('Forgot Password'!J2:J34,"Fail")+COUNTIF('Supplier Onboarding'!J2:J256,"Fail")+COUNTIF('Buyer Onboarding'!J2:J223,"Fail")+COUNTIF('Supplier Dashboard page'!J2:J109,"Fail")+COUNTIF('Supplier Buyer page'!J2:J115,"Fail")+COUNTIF('Supplier Reports Page'!J2:J75,"Fail")+COUNTIF('Supplier Invoices Page'!J2:J132,"Fail")+COUNTIF('Supplier Admin page '!J2:J84,"Fail")+COUNTIF('Supplier Help and Support Page'!J2:J55,"Fail")+COUNTIF('Supplier Entity'!J2:J305,"Fail")+COUNTIF('Buyer Dashboard'!J2:J83,"Fail")+COUNTIF('Add Supplier Page'!J2:J43,"Fail")+COUNTIF('Buyer Report Page'!J2:J75,"Fail")+COUNTIF('Buyer Help and Support Page'!J2:J55,"Fail")+COUNTIF('Buyer Entity Page'!J2:J258,"Fail")+COUNTIF('Buyer Add Card Page '!J2:J38,"Fail")+COUNTIF('Buyer Payable Page'!J2:J85,"Fail")+COUNTIF('Email Notification'!J2:J82,"Fail")+COUNTIF('In_App Notification'!J2:J65,"Fail")),0) -> 0.84848485 | H17: =COUNTIF(Register!E2:E41,"High")+COUNTIF(Login!E2:E34,"High")+COUNTIF('Forgot Password'!E2:E34,"High")+COUNTIF('Supplier Onboarding'!E2:E256,"High")+COUNTIF('Buyer Onboarding'!E2:E223,"High")+COUNTIF('Supplier Dashboard page'!E2:E109,"High")+COUNTIF('Supplier Buyer page'!E2:E115,"High")+COUNTIF('Supplier Reports Page'!E2:E75,"High")+COUNTIF('Supplier Invoices Page'!E2:E132,"High")+COUNTIF('Supplier Admin page '!E2:E84,"High")+COUNTIF('Supplier Help and Support Page'!E2:E55,"High")+COUNTIF('Supplier Entity'!E2:E305,"High")+COUNTIF('Buyer Dashboard'!E2:E83,"High")+COUNTIF('Add Supplier Page'!E2:E43,"High")+COUNTIF('Buyer Report Page'!E2:E75,"High")+COUNTIF('Buyer Help and Support Page'!E2:E55,"High")+COUNTIF('Buyer Entity Page'!E2:E258,"High")+COUNTIF('Buyer Add Card Page '!E2:E38,"High")+COUNTIF('Buyer Payable Page'!E2:E85,"High")+COUNTIF('Email Notification'!E2:E82,"High")+COUNTIF('In_App Notification'!E2:E65,"High") -> 768 | K17: =COUNTIF(Register!E2:E41,"Medium")+COUNTIF(Login!E2:E34,"Medium")+COUNTIF('Forgot Password'!E2:E34,"Medium")+COUNTIF('Supplier Onboarding'!E2:E256,"Medium")+COUNTIF('Buyer Onboarding'!E2:E223,"Medium")+COUNTIF('Supplier Dashboard page'!E2:E109,"Medium")+COUNTIF('Supplier Buyer page'!E2:E115,"Medium")+COUNTIF('Supplier Reports Page'!E2:E75,"Medium")+COUNTIF('Supplier Invoices Page'!E2:E132,"Medium")+COUNTIF('Supplier Admin page '!E2:E84,"Medium")+COUNTIF('Supplier Help and Support Page'!E2:E55,"Medium")+COUNTIF('Supplier Entity'!E2:E305,"Medium")+COUNTIF('Buyer Dashboard'!E2:E83,"Medium")+COUNTIF('Add Supplier Page'!E2:E43,"Medium")+COUNTIF('Buyer Report Page'!E2:E75,"Medium")+COUNTIF('Buyer Help and Support Page'!E2:E55,"Medium")+COUNTIF('Buyer Entity Page'!E2:E258,"Medium")+COUNTIF('Buyer Add Card Page '!E2:E38,"Medium")+COUNTIF('Buyer Payable Page'!E2:E85,"Medium")+COUNTIF('Email Notification'!E2:E82,"Medium")+COUNTIF('In_App Notification'!E2:E65,"Medium") -> 1119 | N17: =COUNTIF(Register!E2:E41,"Low")+COUNTIF(Login!E2:E34,"Low")+COUNTIF('Forgot Password'!E2:E34,"Low")+COUNTIF('Supplier Onboarding'!E2:E256,"Low")+COUNTIF('Buyer Onboarding'!E2:E223,"Low")+COUNTIF('Supplier Dashboard page'!E2:E109,"Low")+COUNTIF('Supplier Buyer page'!E2:E115,"Low")+COUNTIF('Supplier Reports Page'!E2:E75,"Low")+COUNTIF('Supplier Invoices Page'!E2:E132,"Low")+COUNTIF('Supplier Admin page '!E2:E84,"Low")+COUNTIF('Supplier Help and Support Page'!E2:E55,"Low")+COUNTIF('Supplier Entity'!E2:E305,"Low")+COUNTIF('Buyer Dashboard'!E2:E83,"Low")+COUNTIF('Add Supplier Page'!E2:E43,"Low")+COUNTIF('Buyer Report Page'!E2:E75,"Low")+COUNTIF('Buyer Help and Support Page'!E2:E55,"Low")+COUNTIF('Buyer Entity Page'!E2:E258,"Low")+COUNTIF('Buyer Add Card Page '!E2:E38,"Low")+COUNTIF('Buyer Payable Page'!E2:E85,"Low")+COUNTIF('Email Notification'!E2:E82,"Low")+COUNTIF('In_App Notification'!E2:E65,"Low") -> 314
B19: TEST CASE TYPE BREAKDOWN (how the suite is composed)
B20: Test Case Type Category | C20: Count | D20: % of Suite
B21: Functional - Positive | C21: =COUNTIF(Register!D2:D41,"Functional - Positive")+COUNTIF(Login!D2:D34,"Functional - Positive")+COUNTIF('Forgot Password'!D2:D34,"Functional - Positive")+COUNTIF('Supplier Onboarding'!D2:D256,"Functional - Positive")+COUNTIF('Buyer Onboarding'!D2:D223,"Functional - Positive")+COUNTIF('Supplier Dashboard page'!D2:D109,"Functional - Positive")+COUNTIF('Supplier Buyer page'!D2:D115,"Functional - Positive")+COUNTIF('Supplier Reports Page'!D2:D75,"Functional - Positive")+COUNTIF('Supplier Invoices Page'!D2:D132,"Functional - Positive")+COUNTIF('Supplier Admin page '!D2:D84,"Functional - Positive")+COUNTIF('Supplier Help and Support Page'!D2:D55,"Functional - Positive")+COUNTIF('Supplier Entity'!D2:D305,"Functional - Positive")+COUNTIF('Buyer Dashboard'!D2:D83,"Functional - Positive")+COUNTIF('Add Supplier Page'!D2:D43,"Functional - Positive")+COUNTIF('Buyer Report Page'!D2:D75,"Functional - Positive")+COUNTIF('Buyer Help and Support Page'!D2:D55,"Functional - Positive")+COUNTIF('Buyer Entity Page'!D2:D258,"Functional - Positive")+COUNTIF('Buyer Add Card Page '!D2:D38,"Functional - Positive")+COUNTIF('Buyer Payable Page'!D2:D85,"Functional - Positive")+COUNTIF('Email Notification'!D2:D82,"Functional - Positive")+COUNTIF('In_App Notification'!D2:D65,"Functional - Positive") -> 179 | D21: =IFERROR(C21/(COUNTA(Register!D2:D41)+COUNTA(Login!D2:D34)+COUNTA('Forgot Password'!D2:D34)+COUNTA('Supplier Onboarding'!D2:D256)+COUNTA('Buyer Onboarding'!D2:D223)+COUNTA('Supplier Dashboard page'!D2:D109)+COUNTA('Supplier Buyer page'!D2:D115)+COUNTA('Supplier Reports Page'!D2:D75)+COUNTA('Supplier Invoices Page'!D2:D132)+COUNTA('Supplier Admin page '!D2:D84)+COUNTA('Supplier Help and Support Page'!D2:D55)+COUNTA('Supplier Entity'!D2:D305)+COUNTA('Buyer Dashboard'!D2:D83)+COUNTA('Add Supplier Page'!D2:D43)+COUNTA('Buyer Report Page'!D2:D75)+COUNTA('Buyer Help and Support Page'!D2:D55)+COUNTA('Buyer Entity Page'!D2:D258)+COUNTA('Buyer Add Card Page '!D2:D38)+COUNTA('Buyer Payable Page'!D2:D85)+COUNTA('Email Notification'!D2:D82)+COUNTA('In_App Notification'!D2:D65)),0) -> 0.08132667
B22: Functional - Negative | C22: =COUNTIF(Register!D2:D41,"Functional - Negative")+COUNTIF(Login!D2:D34,"Functional - Negative")+COUNTIF('Forgot Password'!D2:D34,"Functional - Negative")+COUNTIF('Supplier Onboarding'!D2:D256,"Functional - Negative")+COUNTIF('Buyer Onboarding'!D2:D223,"Functional - Negative")+COUNTIF('Supplier Dashboard page'!D2:D109,"Functional - Negative")+COUNTIF('Supplier Buyer page'!D2:D115,"Functional - Negative")+COUNTIF('Supplier Reports Page'!D2:D75,"Functional - Negative")+COUNTIF('Supplier Invoices Page'!D2:D132,"Functional - Negative")+COUNTIF('Supplier Admin page '!D2:D84,"Functional - Negative")+COUNTIF('Supplier Help and Support Page'!D2:D55,"Functional - Negative")+COUNTIF('Supplier Entity'!D2:D305,"Functional - Negative")+COUNTIF('Buyer Dashboard'!D2:D83,"Functional - Negative")+COUNTIF('Add Supplier Page'!D2:D43,"Functional - Negative")+COUNTIF('Buyer Report Page'!D2:D75,"Functional - Negative")+COUNTIF('Buyer Help and Support Page'!D2:D55,"Functional - Negative")+COUNTIF('Buyer Entity Page'!D2:D258,"Functional - Negative")+COUNTIF('Buyer Add Card Page '!D2:D38,"Functional - Negative")+COUNTIF('Buyer Payable Page'!D2:D85,"Functional - Negative")+COUNTIF('Email Notification'!D2:D82,"Functional - Negative")+COUNTIF('In_App Notification'!D2:D65,"Functional - Negative") -> 11 | D22: =IFERROR(C22/(COUNTA(Register!D2:D41)+COUNTA(Login!D2:D34)+COUNTA('Forgot Password'!D2:D34)+COUNTA('Supplier Onboarding'!D2:D256)+COUNTA('Buyer Onboarding'!D2:D223)+COUNTA('Supplier Dashboard page'!D2:D109)+COUNTA('Supplier Buyer page'!D2:D115)+COUNTA('Supplier Reports Page'!D2:D75)+COUNTA('Supplier Invoices Page'!D2:D132)+COUNTA('Supplier Admin page '!D2:D84)+COUNTA('Supplier Help and Support Page'!D2:D55)+COUNTA('Supplier Entity'!D2:D305)+COUNTA('Buyer Dashboard'!D2:D83)+COUNTA('Add Supplier Page'!D2:D43)+COUNTA('Buyer Report Page'!D2:D75)+COUNTA('Buyer Help and Support Page'!D2:D55)+COUNTA('Buyer Entity Page'!D2:D258)+COUNTA('Buyer Add Card Page '!D2:D38)+COUNTA('Buyer Payable Page'!D2:D85)+COUNTA('Email Notification'!D2:D82)+COUNTA('In_App Notification'!D2:D65)),0) -> 0.0049977283
B23: Validation - Positive | C23: =COUNTIF(Register!D2:D41,"Validation - Positive")+COUNTIF(Login!D2:D34,"Validation - Positive")+COUNTIF('Forgot Password'!D2:D34,"Validation - Positive")+COUNTIF('Supplier Onboarding'!D2:D256,"Validation - Positive")+COUNTIF('Buyer Onboarding'!D2:D223,"Validation - Positive")+COUNTIF('Supplier Dashboard page'!D2:D109,"Validation - Positive")+COUNTIF('Supplier Buyer page'!D2:D115,"Validation - Positive")+COUNTIF('Supplier Reports Page'!D2:D75,"Validation - Positive")+COUNTIF('Supplier Invoices Page'!D2:D132,"Validation - Positive")+COUNTIF('Supplier Admin page '!D2:D84,"Validation - Positive")+COUNTIF('Supplier Help and Support Page'!D2:D55,"Validation - Positive")+COUNTIF('Supplier Entity'!D2:D305,"Validation - Positive")+COUNTIF('Buyer Dashboard'!D2:D83,"Validation - Positive")+COUNTIF('Add Supplier Page'!D2:D43,"Validation - Positive")+COUNTIF('Buyer Report Page'!D2:D75,"Validation - Positive")+COUNTIF('Buyer Help and Support Page'!D2:D55,"Validation - Positive")+COUNTIF('Buyer Entity Page'!D2:D258,"Validation - Positive")+COUNTIF('Buyer Add Card Page '!D2:D38,"Validation - Positive")+COUNTIF('Buyer Payable Page'!D2:D85,"Validation - Positive")+COUNTIF('Email Notification'!D2:D82,"Validation - Positive")+COUNTIF('In_App Notification'!D2:D65,"Validation - Positive") -> 54 | D23: =IFERROR(C23/(COUNTA(Register!D2:D41)+COUNTA(Login!D2:D34)+COUNTA('Forgot Password'!D2:D34)+COUNTA('Supplier Onboarding'!D2:D256)+COUNTA('Buyer Onboarding'!D2:D223)+COUNTA('Supplier Dashboard page'!D2:D109)+COUNTA('Supplier Buyer page'!D2:D115)+COUNTA('Supplier Reports Page'!D2:D75)+COUNTA('Supplier Invoices Page'!D2:D132)+COUNTA('Supplier Admin page '!D2:D84)+COUNTA('Supplier Help and Support Page'!D2:D55)+COUNTA('Supplier Entity'!D2:D305)+COUNTA('Buyer Dashboard'!D2:D83)+COUNTA('Add Supplier Page'!D2:D43)+COUNTA('Buyer Report Page'!D2:D75)+COUNTA('Buyer Help and Support Page'!D2:D55)+COUNTA('Buyer Entity Page'!D2:D258)+COUNTA('Buyer Add Card Page '!D2:D38)+COUNTA('Buyer Payable Page'!D2:D85)+COUNTA('Email Notification'!D2:D82)+COUNTA('In_App Notification'!D2:D65)),0) -> 0.024534303
B24: Validation - Negative | C24: =COUNTIF(Register!D2:D41,"Validation - Negative")+COUNTIF(Login!D2:D34,"Validation - Negative")+COUNTIF('Forgot Password'!D2:D34,"Validation - Negative")+COUNTIF('Supplier Onboarding'!D2:D256,"Validation - Negative")+COUNTIF('Buyer Onboarding'!D2:D223,"Validation - Negative")+COUNTIF('Supplier Dashboard page'!D2:D109,"Validation - Negative")+COUNTIF('Supplier Buyer page'!D2:D115,"Validation - Negative")+COUNTIF('Supplier Reports Page'!D2:D75,"Validation - Negative")+COUNTIF('Supplier Invoices Page'!D2:D132,"Validation - Negative")+COUNTIF('Supplier Admin page '!D2:D84,"Validation - Negative")+COUNTIF('Supplier Help and Support Page'!D2:D55,"Validation - Negative")+COUNTIF('Supplier Entity'!D2:D305,"Validation - Negative")+COUNTIF('Buyer Dashboard'!D2:D83,"Validation - Negative")+COUNTIF('Add Supplier Page'!D2:D43,"Validation - Negative")+COUNTIF('Buyer Report Page'!D2:D75,"Validation - Negative")+COUNTIF('Buyer Help and Support Page'!D2:D55,"Validation - Negative")+COUNTIF('Buyer Entity Page'!D2:D258,"Validation - Negative")+COUNTIF('Buyer Add Card Page '!D2:D38,"Validation - Negative")+COUNTIF('Buyer Payable Page'!D2:D85,"Validation - Negative")+COUNTIF('Email Notification'!D2:D82,"Validation - Negative")+COUNTIF('In_App Notification'!D2:D65,"Validation - Negative") -> 122 | D24: =IFERROR(C24/(COUNTA(Register!D2:D41)+COUNTA(Login!D2:D34)+COUNTA('Forgot Password'!D2:D34)+COUNTA('Supplier Onboarding'!D2:D256)+COUNTA('Buyer Onboarding'!D2:D223)+COUNTA('Supplier Dashboard page'!D2:D109)+COUNTA('Supplier Buyer page'!D2:D115)+COUNTA('Supplier Reports Page'!D2:D75)+COUNTA('Supplier Invoices Page'!D2:D132)+COUNTA('Supplier Admin page '!D2:D84)+COUNTA('Supplier Help and Support Page'!D2:D55)+COUNTA('Supplier Entity'!D2:D305)+COUNTA('Buyer Dashboard'!D2:D83)+COUNTA('Add Supplier Page'!D2:D43)+COUNTA('Buyer Report Page'!D2:D75)+COUNTA('Buyer Help and Support Page'!D2:D55)+COUNTA('Buyer Entity Page'!D2:D258)+COUNTA('Buyer Add Card Page '!D2:D38)+COUNTA('Buyer Payable Page'!D2:D85)+COUNTA('Email Notification'!D2:D82)+COUNTA('In_App Notification'!D2:D65)),0) -> 0.05542935
B25: Functionality - Positive | C25: =COUNTIF(Register!D2:D41,"Functionality - Positive")+COUNTIF(Login!D2:D34,"Functionality - Positive")+COUNTIF('Forgot Password'!D2:D34,"Functionality - Positive")+COUNTIF('Supplier Onboarding'!D2:D256,"Functionality - Positive")+COUNTIF('Buyer Onboarding'!D2:D223,"Functionality - Positive")+COUNTIF('Supplier Dashboard page'!D2:D109,"Functionality - Positive")+COUNTIF('Supplier Buyer page'!D2:D115,"Functionality - Positive")+COUNTIF('Supplier Reports Page'!D2:D75,"Functionality - Positive")+COUNTIF('Supplier Invoices Page'!D2:D132,"Functionality - Positive")+COUNTIF('Supplier Admin page '!D2:D84,"Functionality - Positive")+COUNTIF('Supplier Help and Support Page'!D2:D55,"Functionality - Positive")+COUNTIF('Supplier Entity'!D2:D305,"Functionality - Positive")+COUNTIF('Buyer Dashboard'!D2:D83,"Functionality - Positive")+COUNTIF('Add Supplier Page'!D2:D43,"Functionality - Positive")+COUNTIF('Buyer Report Page'!D2:D75,"Functionality - Positive")+COUNTIF('Buyer Help and Support Page'!D2:D55,"Functionality - Positive")+COUNTIF('Buyer Entity Page'!D2:D258,"Functionality - Positive")+COUNTIF('Buyer Add Card Page '!D2:D38,"Functionality - Positive")+COUNTIF('Buyer Payable Page'!D2:D85,"Functionality - Positive")+COUNTIF('Email Notification'!D2:D82,"Functionality - Positive")+COUNTIF('In_App Notification'!D2:D65,"Functionality - Positive") -> 33 | D25: =IFERROR(C25/(COUNTA(Register!D2:D41)+COUNTA(Login!D2:D34)+COUNTA('Forgot Password'!D2:D34)+COUNTA('Supplier Onboarding'!D2:D256)+COUNTA('Buyer Onboarding'!D2:D223)+COUNTA('Supplier Dashboard page'!D2:D109)+COUNTA('Supplier Buyer page'!D2:D115)+COUNTA('Supplier Reports Page'!D2:D75)+COUNTA('Supplier Invoices Page'!D2:D132)+COUNTA('Supplier Admin page '!D2:D84)+COUNTA('Supplier Help and Support Page'!D2:D55)+COUNTA('Supplier Entity'!D2:D305)+COUNTA('Buyer Dashboard'!D2:D83)+COUNTA('Add Supplier Page'!D2:D43)+COUNTA('Buyer Report Page'!D2:D75)+COUNTA('Buyer Help and Support Page'!D2:D55)+COUNTA('Buyer Entity Page'!D2:D258)+COUNTA('Buyer Add Card Page '!D2:D38)+COUNTA('Buyer Payable Page'!D2:D85)+COUNTA('Email Notification'!D2:D82)+COUNTA('In_App Notification'!D2:D65)),0) -> 0.014993185
B26: Functionality - Negative | C26: =COUNTIF(Register!D2:D41,"Functionality - Negative")+COUNTIF(Login!D2:D34,"Functionality - Negative")+COUNTIF('Forgot Password'!D2:D34,"Functionality - Negative")+COUNTIF('Supplier Onboarding'!D2:D256,"Functionality - Negative")+COUNTIF('Buyer Onboarding'!D2:D223,"Functionality - Negative")+COUNTIF('Supplier Dashboard page'!D2:D109,"Functionality - Negative")+COUNTIF('Supplier Buyer page'!D2:D115,"Functionality - Negative")+COUNTIF('Supplier Reports Page'!D2:D75,"Functionality - Negative")+COUNTIF('Supplier Invoices Page'!D2:D132,"Functionality - Negative")+COUNTIF('Supplier Admin page '!D2:D84,"Functionality - Negative")+COUNTIF('Supplier Help and Support Page'!D2:D55,"Functionality - Negative")+COUNTIF('Supplier Entity'!D2:D305,"Functionality - Negative")+COUNTIF('Buyer Dashboard'!D2:D83,"Functionality - Negative")+COUNTIF('Add Supplier Page'!D2:D43,"Functionality - Negative")+COUNTIF('Buyer Report Page'!D2:D75,"Functionality - Negative")+COUNTIF('Buyer Help and Support Page'!D2:D55,"Functionality - Negative")+COUNTIF('Buyer Entity Page'!D2:D258,"Functionality - Negative")+COUNTIF('Buyer Add Card Page '!D2:D38,"Functionality - Negative")+COUNTIF('Buyer Payable Page'!D2:D85,"Functionality - Negative")+COUNTIF('Email Notification'!D2:D82,"Functionality - Negative")+COUNTIF('In_App Notification'!D2:D65,"Functionality - Negative") -> 6 | D26: =IFERROR(C26/(COUNTA(Register!D2:D41)+COUNTA(Login!D2:D34)+COUNTA('Forgot Password'!D2:D34)+COUNTA('Supplier Onboarding'!D2:D256)+COUNTA('Buyer Onboarding'!D2:D223)+COUNTA('Supplier Dashboard page'!D2:D109)+COUNTA('Supplier Buyer page'!D2:D115)+COUNTA('Supplier Reports Page'!D2:D75)+COUNTA('Supplier Invoices Page'!D2:D132)+COUNTA('Supplier Admin page '!D2:D84)+COUNTA('Supplier Help and Support Page'!D2:D55)+COUNTA('Supplier Entity'!D2:D305)+COUNTA('Buyer Dashboard'!D2:D83)+COUNTA('Add Supplier Page'!D2:D43)+COUNTA('Buyer Report Page'!D2:D75)+COUNTA('Buyer Help and Support Page'!D2:D55)+COUNTA('Buyer Entity Page'!D2:D258)+COUNTA('Buyer Add Card Page '!D2:D38)+COUNTA('Buyer Payable Page'!D2:D85)+COUNTA('Email Notification'!D2:D82)+COUNTA('In_App Notification'!D2:D65)),0) -> 0.0027260336
B27: Calculation - Positive | C27: =COUNTIF(Register!D2:D41,"Calculation - Positive")+COUNTIF(Login!D2:D34,"Calculation - Positive")+COUNTIF('Forgot Password'!D2:D34,"Calculation - Positive")+COUNTIF('Supplier Onboarding'!D2:D256,"Calculation - Positive")+COUNTIF('Buyer Onboarding'!D2:D223,"Calculation - Positive")+COUNTIF('Supplier Dashboard page'!D2:D109,"Calculation - Positive")+COUNTIF('Supplier Buyer page'!D2:D115,"Calculation - Positive")+COUNTIF('Supplier Reports Page'!D2:D75,"Calculation - Positive")+COUNTIF('Supplier Invoices Page'!D2:D132,"Calculation - Positive")+COUNTIF('Supplier Admin page '!D2:D84,"Calculation - Positive")+COUNTIF('Supplier Help and Support Page'!D2:D55,"Calculation - Positive")+COUNTIF('Supplier Entity'!D2:D305,"Calculation - Positive")+COUNTIF('Buyer Dashboard'!D2:D83,"Calculation - Positive")+COUNTIF('Add Supplier Page'!D2:D43,"Calculation - Positive")+COUNTIF('Buyer Report Page'!D2:D75,"Calculation - Positive")+COUNTIF('Buyer Help and Support Page'!D2:D55,"Calculation - Positive")+COUNTIF('Buyer Entity Page'!D2:D258,"Calculation - Positive")+COUNTIF('Buyer Add Card Page '!D2:D38,"Calculation - Positive")+COUNTIF('Buyer Payable Page'!D2:D85,"Calculation - Positive")+COUNTIF('Email Notification'!D2:D82,"Calculation - Positive")+COUNTIF('In_App Notification'!D2:D65,"Calculation - Positive") -> 16 | D27: =IFERROR(C27/(COUNTA(Register!D2:D41)+COUNTA(Login!D2:D34)+COUNTA('Forgot Password'!D2:D34)+COUNTA('Supplier Onboarding'!D2:D256)+COUNTA('Buyer Onboarding'!D2:D223)+COUNTA('Supplier Dashboard page'!D2:D109)+COUNTA('Supplier Buyer page'!D2:D115)+COUNTA('Supplier Reports Page'!D2:D75)+COUNTA('Supplier Invoices Page'!D2:D132)+COUNTA('Supplier Admin page '!D2:D84)+COUNTA('Supplier Help and Support Page'!D2:D55)+COUNTA('Supplier Entity'!D2:D305)+COUNTA('Buyer Dashboard'!D2:D83)+COUNTA('Add Supplier Page'!D2:D43)+COUNTA('Buyer Report Page'!D2:D75)+COUNTA('Buyer Help and Support Page'!D2:D55)+COUNTA('Buyer Entity Page'!D2:D258)+COUNTA('Buyer Add Card Page '!D2:D38)+COUNTA('Buyer Payable Page'!D2:D85)+COUNTA('Email Notification'!D2:D82)+COUNTA('In_App Notification'!D2:D65)),0) -> 0.007269423
B28: Calculation - Negative | C28: =COUNTIF(Register!D2:D41,"Calculation - Negative")+COUNTIF(Login!D2:D34,"Calculation - Negative")+COUNTIF('Forgot Password'!D2:D34,"Calculation - Negative")+COUNTIF('Supplier Onboarding'!D2:D256,"Calculation - Negative")+COUNTIF('Buyer Onboarding'!D2:D223,"Calculation - Negative")+COUNTIF('Supplier Dashboard page'!D2:D109,"Calculation - Negative")+COUNTIF('Supplier Buyer page'!D2:D115,"Calculation - Negative")+COUNTIF('Supplier Reports Page'!D2:D75,"Calculation - Negative")+COUNTIF('Supplier Invoices Page'!D2:D132,"Calculation - Negative")+COUNTIF('Supplier Admin page '!D2:D84,"Calculation - Negative")+COUNTIF('Supplier Help and Support Page'!D2:D55,"Calculation - Negative")+COUNTIF('Supplier Entity'!D2:D305,"Calculation - Negative")+COUNTIF('Buyer Dashboard'!D2:D83,"Calculation - Negative")+COUNTIF('Add Supplier Page'!D2:D43,"Calculation - Negative")+COUNTIF('Buyer Report Page'!D2:D75,"Calculation - Negative")+COUNTIF('Buyer Help and Support Page'!D2:D55,"Calculation - Negative")+COUNTIF('Buyer Entity Page'!D2:D258,"Calculation - Negative")+COUNTIF('Buyer Add Card Page '!D2:D38,"Calculation - Negative")+COUNTIF('Buyer Payable Page'!D2:D85,"Calculation - Negative")+COUNTIF('Email Notification'!D2:D82,"Calculation - Negative")+COUNTIF('In_App Notification'!D2:D65,"Calculation - Negative") -> 5 | D28: =IFERROR(C28/(COUNTA(Register!D2:D41)+COUNTA(Login!D2:D34)+COUNTA('Forgot Password'!D2:D34)+COUNTA('Supplier Onboarding'!D2:D256)+COUNTA('Buyer Onboarding'!D2:D223)+COUNTA('Supplier Dashboard page'!D2:D109)+COUNTA('Supplier Buyer page'!D2:D115)+COUNTA('Supplier Reports Page'!D2:D75)+COUNTA('Supplier Invoices Page'!D2:D132)+COUNTA('Supplier Admin page '!D2:D84)+COUNTA('Supplier Help and Support Page'!D2:D55)+COUNTA('Supplier Entity'!D2:D305)+COUNTA('Buyer Dashboard'!D2:D83)+COUNTA('Add Supplier Page'!D2:D43)+COUNTA('Buyer Report Page'!D2:D75)+COUNTA('Buyer Help and Support Page'!D2:D55)+COUNTA('Buyer Entity Page'!D2:D258)+COUNTA('Buyer Add Card Page '!D2:D38)+COUNTA('Buyer Payable Page'!D2:D85)+COUNTA('Email Notification'!D2:D82)+COUNTA('In_App Notification'!D2:D65)),0) -> 0.0022716947
B29: Positive (generic) | C29: =COUNTIF(Register!D2:D41,"Positive")+COUNTIF(Login!D2:D34,"Positive")+COUNTIF('Forgot Password'!D2:D34,"Positive")+COUNTIF('Supplier Onboarding'!D2:D256,"Positive")+COUNTIF('Buyer Onboarding'!D2:D223,"Positive")+COUNTIF('Supplier Dashboard page'!D2:D109,"Positive")+COUNTIF('Supplier Buyer page'!D2:D115,"Positive")+COUNTIF('Supplier Reports Page'!D2:D75,"Positive")+COUNTIF('Supplier Invoices Page'!D2:D132,"Positive")+COUNTIF('Supplier Admin page '!D2:D84,"Positive")+COUNTIF('Supplier Help and Support Page'!D2:D55,"Positive")+COUNTIF('Supplier Entity'!D2:D305,"Positive")+COUNTIF('Buyer Dashboard'!D2:D83,"Positive")+COUNTIF('Add Supplier Page'!D2:D43,"Positive")+COUNTIF('Buyer Report Page'!D2:D75,"Positive")+COUNTIF('Buyer Help and Support Page'!D2:D55,"Positive")+COUNTIF('Buyer Entity Page'!D2:D258,"Positive")+COUNTIF('Buyer Add Card Page '!D2:D38,"Positive")+COUNTIF('Buyer Payable Page'!D2:D85,"Positive")+COUNTIF('Email Notification'!D2:D82,"Positive")+COUNTIF('In_App Notification'!D2:D65,"Positive") -> 790 | D29: =IFERROR(C29/(COUNTA(Register!D2:D41)+COUNTA(Login!D2:D34)+COUNTA('Forgot Password'!D2:D34)+COUNTA('Supplier Onboarding'!D2:D256)+COUNTA('Buyer Onboarding'!D2:D223)+COUNTA('Supplier Dashboard page'!D2:D109)+COUNTA('Supplier Buyer page'!D2:D115)+COUNTA('Supplier Reports Page'!D2:D75)+COUNTA('Supplier Invoices Page'!D2:D132)+COUNTA('Supplier Admin page '!D2:D84)+COUNTA('Supplier Help and Support Page'!D2:D55)+COUNTA('Supplier Entity'!D2:D305)+COUNTA('Buyer Dashboard'!D2:D83)+COUNTA('Add Supplier Page'!D2:D43)+COUNTA('Buyer Report Page'!D2:D75)+COUNTA('Buyer Help and Support Page'!D2:D55)+COUNTA('Buyer Entity Page'!D2:D258)+COUNTA('Buyer Add Card Page '!D2:D38)+COUNTA('Buyer Payable Page'!D2:D85)+COUNTA('Email Notification'!D2:D82)+COUNTA('In_App Notification'!D2:D65)),0) -> 0.35892776
B30: Negative (generic) | C30: =COUNTIF(Register!D2:D41,"Negative")+COUNTIF(Login!D2:D34,"Negative")+COUNTIF('Forgot Password'!D2:D34,"Negative")+COUNTIF('Supplier Onboarding'!D2:D256,"Negative")+COUNTIF('Buyer Onboarding'!D2:D223,"Negative")+COUNTIF('Supplier Dashboard page'!D2:D109,"Negative")+COUNTIF('Supplier Buyer page'!D2:D115,"Negative")+COUNTIF('Supplier Reports Page'!D2:D75,"Negative")+COUNTIF('Supplier Invoices Page'!D2:D132,"Negative")+COUNTIF('Supplier Admin page '!D2:D84,"Negative")+COUNTIF('Supplier Help and Support Page'!D2:D55,"Negative")+COUNTIF('Supplier Entity'!D2:D305,"Negative")+COUNTIF('Buyer Dashboard'!D2:D83,"Negative")+COUNTIF('Add Supplier Page'!D2:D43,"Negative")+COUNTIF('Buyer Report Page'!D2:D75,"Negative")+COUNTIF('Buyer Help and Support Page'!D2:D55,"Negative")+COUNTIF('Buyer Entity Page'!D2:D258,"Negative")+COUNTIF('Buyer Add Card Page '!D2:D38,"Negative")+COUNTIF('Buyer Payable Page'!D2:D85,"Negative")+COUNTIF('Email Notification'!D2:D82,"Negative")+COUNTIF('In_App Notification'!D2:D65,"Negative") -> 976 | D30: =IFERROR(C30/(COUNTA(Register!D2:D41)+COUNTA(Login!D2:D34)+COUNTA('Forgot Password'!D2:D34)+COUNTA('Supplier Onboarding'!D2:D256)+COUNTA('Buyer Onboarding'!D2:D223)+COUNTA('Supplier Dashboard page'!D2:D109)+COUNTA('Supplier Buyer page'!D2:D115)+COUNTA('Supplier Reports Page'!D2:D75)+COUNTA('Supplier Invoices Page'!D2:D132)+COUNTA('Supplier Admin page '!D2:D84)+COUNTA('Supplier Help and Support Page'!D2:D55)+COUNTA('Supplier Entity'!D2:D305)+COUNTA('Buyer Dashboard'!D2:D83)+COUNTA('Add Supplier Page'!D2:D43)+COUNTA('Buyer Report Page'!D2:D75)+COUNTA('Buyer Help and Support Page'!D2:D55)+COUNTA('Buyer Entity Page'!D2:D258)+COUNTA('Buyer Add Card Page '!D2:D38)+COUNTA('Buyer Payable Page'!D2:D85)+COUNTA('Email Notification'!D2:D82)+COUNTA('In_App Notification'!D2:D65)),0) -> 0.4434348
B31: Defect - Functional | C31: =COUNTIF(Register!D2:D41,"Defect - Functional")+COUNTIF(Login!D2:D34,"Defect - Functional")+COUNTIF('Forgot Password'!D2:D34,"Defect - Functional")+COUNTIF('Supplier Onboarding'!D2:D256,"Defect - Functional")+COUNTIF('Buyer Onboarding'!D2:D223,"Defect - Functional")+COUNTIF('Supplier Dashboard page'!D2:D109,"Defect - Functional")+COUNTIF('Supplier Buyer page'!D2:D115,"Defect - Functional")+COUNTIF('Supplier Reports Page'!D2:D75,"Defect - Functional")+COUNTIF('Supplier Invoices Page'!D2:D132,"Defect - Functional")+COUNTIF('Supplier Admin page '!D2:D84,"Defect - Functional")+COUNTIF('Supplier Help and Support Page'!D2:D55,"Defect - Functional")+COUNTIF('Supplier Entity'!D2:D305,"Defect - Functional")+COUNTIF('Buyer Dashboard'!D2:D83,"Defect - Functional")+COUNTIF('Add Supplier Page'!D2:D43,"Defect - Functional")+COUNTIF('Buyer Report Page'!D2:D75,"Defect - Functional")+COUNTIF('Buyer Help and Support Page'!D2:D55,"Defect - Functional")+COUNTIF('Buyer Entity Page'!D2:D258,"Defect - Functional")+COUNTIF('Buyer Add Card Page '!D2:D38,"Defect - Functional")+COUNTIF('Buyer Payable Page'!D2:D85,"Defect - Functional")+COUNTIF('Email Notification'!D2:D82,"Defect - Functional")+COUNTIF('In_App Notification'!D2:D65,"Defect - Functional") -> 2 | D31: =IFERROR(C31/(COUNTA(Register!D2:D41)+COUNTA(Login!D2:D34)+COUNTA('Forgot Password'!D2:D34)+COUNTA('Supplier Onboarding'!D2:D256)+COUNTA('Buyer Onboarding'!D2:D223)+COUNTA('Supplier Dashboard page'!D2:D109)+COUNTA('Supplier Buyer page'!D2:D115)+COUNTA('Supplier Reports Page'!D2:D75)+COUNTA('Supplier Invoices Page'!D2:D132)+COUNTA('Supplier Admin page '!D2:D84)+COUNTA('Supplier Help and Support Page'!D2:D55)+COUNTA('Supplier Entity'!D2:D305)+COUNTA('Buyer Dashboard'!D2:D83)+COUNTA('Add Supplier Page'!D2:D43)+COUNTA('Buyer Report Page'!D2:D75)+COUNTA('Buyer Help and Support Page'!D2:D55)+COUNTA('Buyer Entity Page'!D2:D258)+COUNTA('Buyer Add Card Page '!D2:D38)+COUNTA('Buyer Payable Page'!D2:D85)+COUNTA('Email Notification'!D2:D82)+COUNTA('In_App Notification'!D2:D65)),0) -> 0.00090867787
B32: Defect - Validation | C32: =COUNTIF(Register!D2:D41,"Defect - Validation")+COUNTIF(Login!D2:D34,"Defect - Validation")+COUNTIF('Forgot Password'!D2:D34,"Defect - Validation")+COUNTIF('Supplier Onboarding'!D2:D256,"Defect - Validation")+COUNTIF('Buyer Onboarding'!D2:D223,"Defect - Validation")+COUNTIF('Supplier Dashboard page'!D2:D109,"Defect - Validation")+COUNTIF('Supplier Buyer page'!D2:D115,"Defect - Validation")+COUNTIF('Supplier Reports Page'!D2:D75,"Defect - Validation")+COUNTIF('Supplier Invoices Page'!D2:D132,"Defect - Validation")+COUNTIF('Supplier Admin page '!D2:D84,"Defect - Validation")+COUNTIF('Supplier Help and Support Page'!D2:D55,"Defect - Validation")+COUNTIF('Supplier Entity'!D2:D305,"Defect - Validation")+COUNTIF('Buyer Dashboard'!D2:D83,"Defect - Validation")+COUNTIF('Add Supplier Page'!D2:D43,"Defect - Validation")+COUNTIF('Buyer Report Page'!D2:D75,"Defect - Validation")+COUNTIF('Buyer Help and Support Page'!D2:D55,"Defect - Validation")+COUNTIF('Buyer Entity Page'!D2:D258,"Defect - Validation")+COUNTIF('Buyer Add Card Page '!D2:D38,"Defect - Validation")+COUNTIF('Buyer Payable Page'!D2:D85,"Defect - Validation")+COUNTIF('Email Notification'!D2:D82,"Defect - Validation")+COUNTIF('In_App Notification'!D2:D65,"Defect - Validation") -> 7 | D32: =IFERROR(C32/(COUNTA(Register!D2:D41)+COUNTA(Login!D2:D34)+COUNTA('Forgot Password'!D2:D34)+COUNTA('Supplier Onboarding'!D2:D256)+COUNTA('Buyer Onboarding'!D2:D223)+COUNTA('Supplier Dashboard page'!D2:D109)+COUNTA('Supplier Buyer page'!D2:D115)+COUNTA('Supplier Reports Page'!D2:D75)+COUNTA('Supplier Invoices Page'!D2:D132)+COUNTA('Supplier Admin page '!D2:D84)+COUNTA('Supplier Help and Support Page'!D2:D55)+COUNTA('Supplier Entity'!D2:D305)+COUNTA('Buyer Dashboard'!D2:D83)+COUNTA('Add Supplier Page'!D2:D43)+COUNTA('Buyer Report Page'!D2:D75)+COUNTA('Buyer Help and Support Page'!D2:D55)+COUNTA('Buyer Entity Page'!D2:D258)+COUNTA('Buyer Add Card Page '!D2:D38)+COUNTA('Buyer Payable Page'!D2:D85)+COUNTA('Email Notification'!D2:D82)+COUNTA('In_App Notification'!D2:D65)),0) -> 0.0031803726
B35: PER-MODULE / SCREEN BREAKDOWN
B36: Module / Screen | C36: Total TCs | D36: Positive | E36: Negative | F36: High | G36: Medium | H36: Low | I36: Pass | J36: Fail | K36: Blocked | L36: Not Executed | M36: Pass Rate % | N36: Execution %
B37: Register | C37: =COUNTA(Register!D2:D41) -> 40 | D37: =COUNTIF(Register!D2:D41,"*Positive*") -> 18 | E37: =COUNTIF(Register!D2:D41,"*Negative*") -> 22 | F37: =COUNTIF(Register!E2:E41,"High") -> 19 | G37: =COUNTIF(Register!E2:E41,"Medium") -> 11 | H37: =COUNTIF(Register!E2:E41,"Low") -> 10 | I37: =COUNTIF(Register!J2:J41,"Pass") -> 0 | J37: =COUNTIF(Register!J2:J41,"Fail") -> 0 | K37: =COUNTIF(Register!J2:J41,"Blocked") -> 0 | L37: =C37-I37-J37-K37 -> 40 | M37: =IFERROR(I37/(I37+J37),0) -> 0 | N37: =IFERROR((I37+J37+K37)/C37,0) -> 0
B38: Login | C38: =COUNTA(Login!D2:D34) -> 33 | D38: =COUNTIF(Login!D2:D34,"*Positive*") -> 16 | E38: =COUNTIF(Login!D2:D34,"*Negative*") -> 17 | F38: =COUNTIF(Login!E2:E34,"High") -> 18 | G38: =COUNTIF(Login!E2:E34,"Medium") -> 10 | H38: =COUNTIF(Login!E2:E34,"Low") -> 5 | I38: =COUNTIF(Login!J2:J34,"Pass") -> 28 | J38: =COUNTIF(Login!J2:J34,"Fail") -> 5 | K38: =COUNTIF(Login!J2:J34,"Blocked") -> 0 | L38: =C38-I38-J38-K38 -> 0 | M38: =IFERROR(I38/(I38+J38),0) -> 0.84848485 | N38: =IFERROR((I38+J38+K38)/C38,0) -> 1
B39: Forgot Password | C39: =COUNTA('Forgot Password'!D2:D34) -> 33 | D39: =COUNTIF('Forgot Password'!D2:D34,"*Positive*") -> 13 | E39: =COUNTIF('Forgot Password'!D2:D34,"*Negative*") -> 20 | F39: =COUNTIF('Forgot Password'!E2:E34,"High") -> 15 | G39: =COUNTIF('Forgot Password'!E2:E34,"Medium") -> 10 | H39: =COUNTIF('Forgot Password'!E2:E34,"Low") -> 8 | I39: =COUNTIF('Forgot Password'!J2:J34,"Pass") -> 0 | J39: =COUNTIF('Forgot Password'!J2:J34,"Fail") -> 0 | K39: =COUNTIF('Forgot Password'!J2:J34,"Blocked") -> 0 | L39: =C39-I39-J39-K39 -> 33 | M39: =IFERROR(I39/(I39+J39),0) -> 0 | N39: =IFERROR((I39+J39+K39)/C39,0) -> 0
B40: Supplier Onboarding | C40: =COUNTA('Supplier Onboarding'!D2:D256) -> 255 | D40: =COUNTIF('Supplier Onboarding'!D2:D256,"*Positive*") -> 89 | E40: =COUNTIF('Supplier Onboarding'!D2:D256,"*Negative*") -> 166 | F40: =COUNTIF('Supplier Onboarding'!E2:E256,"High") -> 43 | G40: =COUNTIF('Supplier Onboarding'!E2:E256,"Medium") -> 166 | H40: =COUNTIF('Supplier Onboarding'!E2:E256,"Low") -> 46 | I40: =COUNTIF('Supplier Onboarding'!J2:J256,"Pass") -> 0 | J40: =COUNTIF('Supplier Onboarding'!J2:J256,"Fail") -> 0 | K40: =COUNTIF('Supplier Onboarding'!J2:J256,"Blocked") -> 0 | L40: =C40-I40-J40-K40 -> 255 | M40: =IFERROR(I40/(I40+J40),0) -> 0 | N40: =IFERROR((I40+J40+K40)/C40,0) -> 0
B41: Buyer Onboarding | C41: =COUNTA('Buyer Onboarding'!D2:D223) -> 222 | D41: =COUNTIF('Buyer Onboarding'!D2:D223,"*Positive*") -> 81 | E41: =COUNTIF('Buyer Onboarding'!D2:D223,"*Negative*") -> 141 | F41: =COUNTIF('Buyer Onboarding'!E2:E223,"High") -> 41 | G41: =COUNTIF('Buyer Onboarding'!E2:E223,"Medium") -> 141 | H41: =COUNTIF('Buyer Onboarding'!E2:E223,"Low") -> 40 | I41: =COUNTIF('Buyer Onboarding'!J2:J223,"Pass") -> 0 | J41: =COUNTIF('Buyer Onboarding'!J2:J223,"Fail") -> 0 | K41: =COUNTIF('Buyer Onboarding'!J2:J223,"Blocked") -> 0 | L41: =C41-I41-J41-K41 -> 222 | M41: =IFERROR(I41/(I41+J41),0) -> 0 | N41: =IFERROR((I41+J41+K41)/C41,0) -> 0
B42: Supplier Dashboard page | C42: =COUNTA('Supplier Dashboard page'!D2:D109) -> 108 | D42: =COUNTIF('Supplier Dashboard page'!D2:D109,"*Positive*") -> 79 | E42: =COUNTIF('Supplier Dashboard page'!D2:D109,"*Negative*") -> 29 | F42: =COUNTIF('Supplier Dashboard page'!E2:E109,"High") -> 57 | G42: =COUNTIF('Supplier Dashboard page'!E2:E109,"Medium") -> 44 | H42: =COUNTIF('Supplier Dashboard page'!E2:E109,"Low") -> 7 | I42: =COUNTIF('Supplier Dashboard page'!J2:J109,"Pass") -> 0 | J42: =COUNTIF('Supplier Dashboard page'!J2:J109,"Fail") -> 0 | K42: =COUNTIF('Supplier Dashboard page'!J2:J109,"Blocked") -> 0 | L42: =C42-I42-J42-K42 -> 108 | M42: =IFERROR(I42/(I42+J42),0) -> 0 | N42: =IFERROR((I42+J42+K42)/C42,0) -> 0
B43: Supplier Buyer page | C43: =COUNTA('Supplier Buyer page'!D2:D115) -> 114 | D43: =COUNTIF('Supplier Buyer page'!D2:D115,"*Positive*") -> 48 | E43: =COUNTIF('Supplier Buyer page'!D2:D115,"*Negative*") -> 66 | F43: =COUNTIF('Supplier Buyer page'!E2:E115,"High") -> 43 | G43: =COUNTIF('Supplier Buyer page'!E2:E115,"Medium") -> 54 | H43: =COUNTIF('Supplier Buyer page'!E2:E115,"Low") -> 17 | I43: =COUNTIF('Supplier Buyer page'!J2:J115,"Pass") -> 0 | J43: =COUNTIF('Supplier Buyer page'!J2:J115,"Fail") -> 0 | K43: =COUNTIF('Supplier Buyer page'!J2:J115,"Blocked") -> 0 | L43: =C43-I43-J43-K43 -> 114 | M43: =IFERROR(I43/(I43+J43),0) -> 0 | N43: =IFERROR((I43+J43+K43)/C43,0) -> 0
B44: Supplier Reports Page | C44: =COUNTA('Supplier Reports Page'!D2:D75) -> 74 | D44: =COUNTIF('Supplier Reports Page'!D2:D75,"*Positive*") -> 40 | E44: =COUNTIF('Supplier Reports Page'!D2:D75,"*Negative*") -> 34 | F44: =COUNTIF('Supplier Reports Page'!E2:E75,"High") -> 34 | G44: =COUNTIF('Supplier Reports Page'!E2:E75,"Medium") -> 33 | H44: =COUNTIF('Supplier Reports Page'!E2:E75,"Low") -> 7 | I44: =COUNTIF('Supplier Reports Page'!J2:J75,"Pass") -> 0 | J44: =COUNTIF('Supplier Reports Page'!J2:J75,"Fail") -> 0 | K44: =COUNTIF('Supplier Reports Page'!J2:J75,"Blocked") -> 0 | L44: =C44-I44-J44-K44 -> 74 | M44: =IFERROR(I44/(I44+J44),0) -> 0 | N44: =IFERROR((I44+J44+K44)/C44,0) -> 0
B45: Supplier Invoices Page | C45: =COUNTA('Supplier Invoices Page'!D2:D132) -> 131 | D45: =COUNTIF('Supplier Invoices Page'!D2:D132,"*Positive*") -> 90 | E45: =COUNTIF('Supplier Invoices Page'!D2:D132,"*Negative*") -> 41 | F45: =COUNTIF('Supplier Invoices Page'!E2:E132,"High") -> 56 | G45: =COUNTIF('Supplier Invoices Page'!E2:E132,"Medium") -> 58 | H45: =COUNTIF('Supplier Invoices Page'!E2:E132,"Low") -> 17 | I45: =COUNTIF('Supplier Invoices Page'!J2:J132,"Pass") -> 0 | J45: =COUNTIF('Supplier Invoices Page'!J2:J132,"Fail") -> 0 | K45: =COUNTIF('Supplier Invoices Page'!J2:J132,"Blocked") -> 0 | L45: =C45-I45-J45-K45 -> 131 | M45: =IFERROR(I45/(I45+J45),0) -> 0 | N45: =IFERROR((I45+J45+K45)/C45,0) -> 0
B46: Supplier Admin page | C46: =COUNTA('Supplier Admin page '!D2:D84) -> 83 | D46: =COUNTIF('Supplier Admin page '!D2:D84,"*Positive*") -> 48 | E46: =COUNTIF('Supplier Admin page '!D2:D84,"*Negative*") -> 35 | F46: =COUNTIF('Supplier Admin page '!E2:E84,"High") -> 44 | G46: =COUNTIF('Supplier Admin page '!E2:E84,"Medium") -> 33 | H46: =COUNTIF('Supplier Admin page '!E2:E84,"Low") -> 6 | I46: =COUNTIF('Supplier Admin page '!J2:J84,"Pass") -> 0 | J46: =COUNTIF('Supplier Admin page '!J2:J84,"Fail") -> 0 | K46: =COUNTIF('Supplier Admin page '!J2:J84,"Blocked") -> 0 | L46: =C46-I46-J46-K46 -> 83 | M46: =IFERROR(I46/(I46+J46),0) -> 0 | N46: =IFERROR((I46+J46+K46)/C46,0) -> 0
B47: Supplier Help and Support Page | C47: =COUNTA('Supplier Help and Support Page'!D2:D55) -> 54 | D47: =COUNTIF('Supplier Help and Support Page'!D2:D55,"*Positive*") -> 37 | E47: =COUNTIF('Supplier Help and Support Page'!D2:D55,"*Negative*") -> 17 | F47: =COUNTIF('Supplier Help and Support Page'!E2:E55,"High") -> 33 | G47: =COUNTIF('Supplier Help and Support Page'!E2:E55,"Medium") -> 13 | H47: =COUNTIF('Supplier Help and Support Page'!E2:E55,"Low") -> 8 | I47: =COUNTIF('Supplier Help and Support Page'!J2:J55,"Pass") -> 0 | J47: =COUNTIF('Supplier Help and Support Page'!J2:J55,"Fail") -> 0 | K47: =COUNTIF('Supplier Help and Support Page'!J2:J55,"Blocked") -> 0 | L47: =C47-I47-J47-K47 -> 54 | M47: =IFERROR(I47/(I47+J47),0) -> 0 | N47: =IFERROR((I47+J47+K47)/C47,0) -> 0
B48: Supplier Entity | C48: =COUNTA('Supplier Entity'!D2:D305) -> 288 | D48: =COUNTIF('Supplier Entity'!D2:D305,"*Positive*") -> 108 | E48: =COUNTIF('Supplier Entity'!D2:D305,"*Negative*") -> 175 | F48: =COUNTIF('Supplier Entity'!E2:E305,"High") -> 50 | G48: =COUNTIF('Supplier Entity'!E2:E305,"Medium") -> 187 | H48: =COUNTIF('Supplier Entity'!E2:E305,"Low") -> 51 | I48: =COUNTIF('Supplier Entity'!J2:J305,"Pass") -> 0 | J48: =COUNTIF('Supplier Entity'!J2:J305,"Fail") -> 0 | K48: =COUNTIF('Supplier Entity'!J2:J305,"Blocked") -> 0 | L48: =C48-I48-J48-K48 -> 288 | M48: =IFERROR(I48/(I48+J48),0) -> 0 | N48: =IFERROR((I48+J48+K48)/C48,0) -> 0
B49: Buyer Dashboard | C49: =COUNTA('Buyer Dashboard'!D2:D83) -> 76 | D49: =COUNTIF('Buyer Dashboard'!D2:D83,"*Positive*") -> 59 | E49: =COUNTIF('Buyer Dashboard'!D2:D83,"*Negative*") -> 17 | F49: =COUNTIF('Buyer Dashboard'!E2:E83,"High") -> 35 | G49: =COUNTIF('Buyer Dashboard'!E2:E83,"Medium") -> 31 | H49: =COUNTIF('Buyer Dashboard'!E2:E83,"Low") -> 10 | I49: =COUNTIF('Buyer Dashboard'!J2:J83,"Pass") -> 0 | J49: =COUNTIF('Buyer Dashboard'!J2:J83,"Fail") -> 0 | K49: =COUNTIF('Buyer Dashboard'!J2:J83,"Blocked") -> 0 | L49: =C49-I49-J49-K49 -> 76 | M49: =IFERROR(I49/(I49+J49),0) -> 0 | N49: =IFERROR((I49+J49+K49)/C49,0) -> 0
...

Sheet Register
A1: Test Case ID | B1: Screen | C1: Test Case Description | D1: Test Case Type | E1: Priority | F1: Test Steps | G1: Test Data | H1: Expected Result | I1: Actual Result | J1: Status | K1: Remarks
A2: TC_REG_AIR_01 | B2: Register - Airlines | C2: Register successfully with all valid mandatory fields | D2: Positive | E2: High | F2: 1. Navigate to Register page 2. Select 'Airlines' tab 3. Enter valid Organisation Name, Mobile Number (with country code), Organisation Email, Password, Confirm Password 4. Click 'Sign Up' | G2: Org Name: Rehan Airlines; Country Code: +971; Mobile: 378457834; Email: rehanairlines@yopmail.com; Password: Test@1234 | H2: Registration succeeds; 'Verification Email Sent!' pop-up is displayed showing the masked registered email | J2: Not Executed
A3: TC_REG_AIR_02 | B3: Register - Airlines | C3: Country code dropdown allows selecting a different code | D3: Positive | E3: Medium | F3: 1. On Register - Airlines, click the country code dropdown 2. Select a different country code 3. Enter mobile number 4. Complete remaining fields and Sign Up | G3: Country Code: +91; Mobile: 9876543210 | H3: Selected country code is applied correctly and reflected in the submitted mobile number; registration proceeds normally | J3: Not Executed
A4: TC_REG_AIR_03 | B4: Register - Airlines | C4: Password Show/Hide toggle works on Register page | D4: Positive | E4: Low | F4: 1. Enter a password in the Password field 2. Click the eye icon on Password field 3. Click the eye icon on Confirm Password field | G4: Password: Test@1234 | H4: Masked password text toggles to plain text and back correctly for both Password and Confirm Password fields independently | J4: Not Executed
A5: TC_REG_AIR_04 | B5: Register - Airlines | C5: Login' link on Register page navigates to Login screen | D5: Positive | E5: Low | F5: 1. On Register - Airlines page, click 'Login' link next to 'Already a user ?' | G5: N/A | H5: User is navigated to the Login screen without submitting the registration form | J5: Not Executed
